<?xml version='1.0'?>
<sdf version='1.7'>
  <model name='ptu_150cm'>
    <link name='tripod_floor_link'>
        <self_collide>0</self_collide>
        <enable_wind>0</enable_wind>
        <kinematic>0</kinematic>
        <pose>-0 0 0 0 -0 0</pose>
        <gravity>1</gravity>
        <visual name='tripod_floor_link_fixed_joint_lump__tripod_mount_link_visual_1'>
          <pose>0.0555 -0.0025 1.50025 -3.13993 0 0</pose>
          <geometry>
            <mesh>
              <uri>package://mapping_custom_description/models/ptu_150cm/meshes/base_link.dae</uri>
            </mesh>
          </geometry>
        </visual>
        <visual name='tripod_floor_link_visual'>
          <pose>0 0 0 0 -0 0</pose>
          <geometry>
            <mesh>
              <scale>1 1 1</scale>
              <uri>package://mapping_custom_description/models/ptu_150cm/meshes/tripod150_link.dae</uri>
            </mesh>
          </geometry>
        </visual>
        <collision name='collision_2'>
          <laser_retro>0</laser_retro>
          <max_contacts>4</max_contacts>
          <pose>0 0.05 0.5 0 -0 0</pose>
          <geometry>
            <box>
              <size>0.5 0.5 1</size>
            </box>
          </geometry>
          <surface>
            <friction>
              <ode>
                <mu>1</mu>
                <mu2>1</mu2>
                <fdir1>0 0 0</fdir1>
                <slip1>0</slip1>
                <slip2>0</slip2>
              </ode>
              <torsional>
                <coefficient>1</coefficient>
                <patch_radius>0</patch_radius>
                <surface_radius>0</surface_radius>
                <use_patch_radius>1</use_patch_radius>
                <ode>
                  <slip>0</slip>
                </ode>
              </torsional>
            </friction>
            <bounce>
              <restitution_coefficient>0</restitution_coefficient>
              <threshold>1e+06</threshold>
            </bounce>
            <contact>
              <collide_without_contact>0</collide_without_contact>
              <collide_without_contact_bitmask>1</collide_without_contact_bitmask>
              <collide_bitmask>1</collide_bitmask>
              <ode>
                <soft_cfm>0</soft_cfm>
                <soft_erp>0.2</soft_erp>
                <kp>1e+13</kp>
                <kd>1</kd>
                <max_vel>0.01</max_vel>
                <min_depth>0</min_depth>
              </ode>
              <bullet>
                <split_impulse>1</split_impulse>
                <split_impulse_penetration_threshold>-0.01</split_impulse_penetration_threshold>
                <soft_cfm>0</soft_cfm>
                <soft_erp>0.2</soft_erp>
                <kp>1e+13</kp>
                <kd>1</kd>
              </bullet>
            </contact>
          </surface>
        </collision>
      </link>
      <link name='os_imu'>
        <pose>0.069003 -0.013119 1.69743 -5e-06 0 0</pose>
        <inertial>
          <pose>-0.006241 0.011763 0.087703 0 -0 0</pose>
          <mass>0.001</mass>
          <inertia>
            <ixx>4.0807e-05</ixx>
            <ixy>-8.68167e-12</ixy>
            <ixz>-5.87751e-10</ixz>
            <iyy>4.0807e-05</iyy>
            <iyz>5.87751e-10</iyz>
            <izz>8.11138e-05</izz>
          </inertia>
        </inertial>
        <self_collide>0</self_collide>
        <enable_wind>0</enable_wind>
        <kinematic>0</kinematic>
      </link>
      <link name='os_lidar'>
        <pose>0.06275 -0.001343 1.76408 5e-06 -0 3.14159</pose>
        <inertial>
          <pose>-1.2e-05 1.2e-05 0.021052 0 -0 0</pose>
          <mass>0.001</mass>
          <inertia>
            <ixx>4.081e-05</ixx>
            <ixy>0</ixy>
            <ixz>0</ixz>
            <iyy>4.081e-05</iyy>
            <iyz>0</iyz>
            <izz>8.111e-05</izz>
          </inertia>
        </inertial>
        <self_collide>0</self_collide>
        <enable_wind>0</enable_wind>
        <kinematic>0</kinematic>
      </link>
      <link name='os_sensor'>
        <pose>0.06275 -0.001344 1.68578 -5e-06 0 0</pose>
        <inertial>
          <pose>-0 0 0.067136 0 -0 0</pose>
          <mass>0.001</mass>
          <inertia>
            <ixx>0.000492149</ixx>
            <ixy>-1.60185e-20</ixy>
            <ixz>-1.09919e-19</ixz>
            <iyy>0.000492149</iyy>
            <iyz>1.10855e-20</iyz>
            <izz>0.000714724</izz>
          </inertia>
        </inertial>
        <self_collide>0</self_collide>
        <enable_wind>0</enable_wind>
        <kinematic>0</kinematic>
      </link>
      <link name='pan_axis_link'>
        <pose>0.0555 -0.0025 1.50025 -3.13993 0 0</pose>
        <inertial>
          <pose>-0.012103 -0.000282 -0.086953 0 -0 0</pose>
          <mass>0.001</mass>
          <inertia>
            <ixx>0.000382616</ixx>
            <ixy>6.27961e-07</ixy>
            <ixz>2.32606e-05</ixz>
            <iyy>0.000811069</iyy>
            <iyz>-4.78192e-07</iyz>
            <izz>0.00053511</izz>
          </inertia>
        </inertial>
        <self_collide>0</self_collide>
        <enable_wind>0</enable_wind>
        <kinematic>0</kinematic>
        <visual name='pan_axis_link_visual'>
          <pose>0 0 0 0 -0 0</pose>
          <geometry>
            <mesh>
              <scale>1 1 1</scale>
              <uri>package://mapping_custom_description/models/ptu_150cm/meshes/body_link.dae</uri>
            </mesh>
          </geometry>
        </visual>
      </link>
      <link name='tilt_axis_link'>
        <pose>0.06275 -0.0025 1.59758 1.57079 -0 0</pose>
        <inertial>
          <pose>2e-06 0.127366 -0.000989 0 -0 0</pose>
          <mass>0.001</mass>
          <inertia>
            <ixx>0.00231891</ixx>
            <ixy>-4.52409e-09</ixy>
            <ixz>4.09872e-09</ixz>
            <iyy>0.00157858</iyy>
            <iyz>7.07827e-06</iyz>
            <izz>0.00219041</izz>
          </inertia>
        </inertial>
        <self_collide>0</self_collide>
        <enable_wind>0</enable_wind>
        <kinematic>0</kinematic>
        <visual name='tilt_axis_link_fixed_joint_lump__lidar_glass_link_visual_1'>
          <pose>0 0 0 0 -0 0</pose>
          <geometry>
            <mesh>
              <scale>1 1 1</scale>
              <uri>package://mapping_custom_description/models/ptu_150cm/meshes/lidar_mid_link.dae</uri>
            </mesh>
          </geometry>
        </visual>
        <visual name='tilt_axis_link_visual'>
          <pose>0 0 0 0 -0 0</pose>
          <geometry>
            <mesh>
              <scale>1 1 1</scale>
              <uri>package://mapping_custom_description/models/ptu_150cm/meshes/lidar_link.dae</uri>
            </mesh>
          </geometry>
        </visual>
        <visual name='tilt_axis_link_fixed_joint_lump__lidar_cap_link_visual_2'>
          <pose>0 0 0 0 -0 0</pose>
          <geometry>
            <mesh>
              <scale>1 1 1</scale>
              <uri>package://mapping_custom_description/models/ptu_150cm/meshes/lidar_top_link.dae</uri>
            </mesh>
          </geometry>
        </visual>
      </link>
      <link name='cam_1'>
       <pose>0.1555 -0.0025 1.7 0 0 0</pose>
       <self_collide>0</self_collide>
       <inertial>
          <pose>0 0 0 0 0 0</pose>
          <mass>0.00000000000000001</mass>
        </inertial>
       <visual name='visual'>
          <pose>0 0 0 0 -0 0</pose>
          <geometry>
            <box>
              <size>0.03 0.03 0.03</size>
            </box>
          </geometry>
        </visual>
      </link>
      <link name='cam_2'>
       <pose> -0.0445 -0.0025 1.7 0 -0 3.14159265359</pose>
       <self_collide>0</self_collide>
       <inertial>
          <pose>0 0 0 0 0 0</pose>
          <mass>0.00000000000000001</mass>
        </inertial>
       <visual name='visual'>
          <pose>0 0 0 0 -0 0</pose>
          <geometry>
            <box>
              <size>0.03 0.03 0.03</size>
            </box>
          </geometry>
        </visual>
      </link>
      <link name='cam_3'>
       <pose> 0.0555 0.0975 1.7 0 -0 1.57079632679</pose>
       <self_collide>0</self_collide>
       <inertial>
          <pose>0 0 0 0 0 0</pose>
          <mass>0.00000000000000001</mass>
        </inertial>
       <visual name='visual'>
          <pose>0 0 0 0 -0 0</pose>
          <geometry>
            <box>
              <size>0.03 0.03 0.03</size>
            </box>
          </geometry>
        </visual>
      </link>
      <link name='cam_4'>
       <pose> 0.0555 -0.1025 1.7 0 -0 -1.57079632679</pose>
       <self_collide>0</self_collide>
       <inertial>
          <pose>0 0 0 0 0 0</pose>
          <mass>0.00000000000000001</mass>
        </inertial>
       <visual name='visual'>
          <pose>0 0 0 0 -0 0</pose>
          <geometry>
            <box>
              <size>0.03 0.03 0.03</size>
            </box>
          </geometry>
        </visual>
      </link>
      <link name='cam_5'>
       <pose> 0.1555 0.0975 1.7 0 -0 0.78539816339</pose>
       <self_collide>0</self_collide>
       <inertial>
          <pose>0 0 0 0 0 0</pose>
          <mass>0.00000000000000001</mass>
        </inertial>
       <visual name='visual'>
          <pose>0 0 0 0 -0 0</pose>
          <geometry>
            <box>
              <size>0.03 0.03 0.03</size>
            </box>
          </geometry>
        </visual>
      </link>
      <link name='cam_6'>
       <pose> 0.1555 -0.1025 1.7 0 -0 -0.78539816339</pose>
       <self_collide>0</self_collide>
       <inertial>
          <pose>0 0 0 0 0 0</pose>
          <mass>0.00000000000000001</mass>
        </inertial>
       <visual name='visual'>
          <pose>0 0 0 0 -0 0</pose>
          <geometry>
            <box>
              <size>0.03 0.03 0.03</size>
            </box>
          </geometry>
        </visual>
      </link>
      <link name='cam_7'>
       <pose> -0.0445 0.0975 1.7 0 -0 2.35619449019</pose>
       <self_collide>0</self_collide>
       <inertial>
          <pose>0 0 0 0 0 0</pose>
          <mass>0.00000000000000001</mass>
        </inertial>
       <visual name='visual'>
          <pose>0 0 0 0 -0 0</pose>
          <geometry>
            <box>
              <size>0.03 0.03 0.03</size>
            </box>
          </geometry>
        </visual>
      </link>
      <link name='cam_8'>
       <pose> -0.0445 -0.1025 1.7 0 -0 -2.35619449019</pose>
       <self_collide>0</self_collide>
       <inertial>
          <pose>0 0 0 0 0 0</pose>
          <mass>0.00000000000000001</mass>
        </inertial>
       <visual name='visual'>
          <pose>0 0 0 0 -0 0</pose>
          <geometry>
            <box>
              <size>0.03 0.03 0.03</size>
            </box>
          </geometry>
        </visual>
      </link>
      <link name='collision_box'>
        <pose>0 0.05 1 0 0 0</pose>
        <self_collide>0</self_collide>
        <collision name='collision'>
          <max_contacts>4</max_contacts>
            <geometry>
                <box>
                    <size>0.5 0.5 1.8</size>
                </box>
            </geometry>
        </collision>
      </link>
      <joint name='collision_joint' type='fixed'>
        <parent>tripod_floor_link</parent>
        <child>collision_box</child>
        <pose>-0 0 -0 0 -0 0</pose>
        <physics>
          <ode>
            <limit>
              <cfm>0</cfm>
              <erp>0.2</erp>
            </limit>
            <suspension>
              <cfm>0</cfm>
              <erp>0.2</erp>
            </suspension>
          </ode>
        </physics>
      </joint>
      <joint name='cam_1_joint' type='fixed'>
        <parent>tilt_axis_link</parent>
        <child>cam_1</child>
        <pose>-0 0 -0 0 -0 0</pose>
        <physics>
          <ode>
            <limit>
              <cfm>0</cfm>
              <erp>0.2</erp>
            </limit>
            <suspension>
              <cfm>0</cfm>
              <erp>0.2</erp>
            </suspension>
          </ode>
        </physics>
      </joint>
      <joint name='cam_2_joint' type='fixed'>
        <parent>tilt_axis_link</parent>
        <child>cam_2</child>
        <pose>-0 0 -0 0 -0 0</pose>
        <physics>
          <ode>
            <limit>
              <cfm>0</cfm>
              <erp>0.2</erp>
            </limit>
            <suspension>
              <cfm>0</cfm>
              <erp>0.2</erp>
            </suspension>
          </ode>
        </physics>
      </joint>
      <joint name='cam_3_joint' type='fixed'>
        <parent>tilt_axis_link</parent>
        <child>cam_3</child>
        <pose>-0 0 -0 0 -0 0</pose>
        <physics>
          <ode>
            <limit>
              <cfm>0</cfm>
              <erp>0.2</erp>
            </limit>
            <suspension>
              <cfm>0</cfm>
              <erp>0.2</erp>
            </suspension>
          </ode>
        </physics>
      </joint>
      <joint name='cam_4_joint' type='fixed'>
        <parent>tilt_axis_link</parent>
        <child>cam_4</child>
        <pose>-0 0 -0 0 -0 0</pose>
        <physics>
          <ode>
            <limit>
              <cfm>0</cfm>
              <erp>0.2</erp>
            </limit>
            <suspension>
              <cfm>0</cfm>
              <erp>0.2</erp>
            </suspension>
          </ode>
        </physics>
      </joint>
      <joint name='cam_5_joint' type='fixed'>
        <parent>tilt_axis_link</parent>
        <child>cam_5</child>
        <pose>-0 0 -0 0 -0 0</pose>
        <physics>
          <ode>
            <limit>
              <cfm>0</cfm>
              <erp>0.2</erp>
            </limit>
            <suspension>
              <cfm>0</cfm>
              <erp>0.2</erp>
            </suspension>
          </ode>
        </physics>
      </joint>
      <joint name='cam_6_joint' type='fixed'>
        <parent>tilt_axis_link</parent>
        <child>cam_6</child>
        <pose>-0 0 -0 0 -0 0</pose>
        <physics>
          <ode>
            <limit>
              <cfm>0</cfm>
              <erp>0.2</erp>
            </limit>
            <suspension>
              <cfm>0</cfm>
              <erp>0.2</erp>
            </suspension>
          </ode>
        </physics>
      </joint>
      <joint name='cam_7_joint' type='fixed'>
        <parent>tilt_axis_link</parent>
        <child>cam_7</child>
        <pose>-0 0 -0 0 -0 0</pose>
        <physics>
          <ode>
            <limit>
              <cfm>0</cfm>
              <erp>0.2</erp>
            </limit>
            <suspension>
              <cfm>0</cfm>
              <erp>0.2</erp>
            </suspension>
          </ode>
        </physics>
      </joint>
      <joint name='cam_8_joint' type='fixed'>
        <parent>tilt_axis_link</parent>
        <child>cam_8</child>
        <pose>-0 0 -0 0 -0 0</pose>
        <physics>
          <ode>
            <limit>
              <cfm>0</cfm>
              <erp>0.2</erp>
            </limit>
            <suspension>
              <cfm>0</cfm>
              <erp>0.2</erp>
            </suspension>
          </ode>
        </physics>
      </joint>
      <joint name='imu_cf_joint' type='fixed'>
        <parent>os_sensor</parent>
        <child>os_imu</child>
        <pose>-0 0 -0 0 -0 0</pose>
        <physics>
          <ode>
            <limit>
              <cfm>0</cfm>
              <erp>0.2</erp>
            </limit>
            <suspension>
              <cfm>0</cfm>
              <erp>0.2</erp>
            </suspension>
          </ode>
        </physics>
      </joint>
      <joint name='lidar_cf_joint' type='revolute'>
        <parent>os_sensor</parent>
        <child>os_lidar</child>
        <pose>-0 -0 -0 0 -0 0</pose>
        <axis>
          <xyz>0 0 1</xyz>
          <limit>
            <lower>-1e+16</lower>
            <upper>1e+16</upper>
            <effort>-1</effort>
            <velocity>-1</velocity>
          </limit>
          <dynamics>
            <spring_reference>0</spring_reference>
            <spring_stiffness>0</spring_stiffness>
            <damping>50</damping>
            <friction>0</friction>
          </dynamics>
        </axis>
        <physics>
          <ode>
            <limit>
              <cfm>0</cfm>
              <erp>0.2</erp>
            </limit>
            <suspension>
              <cfm>0</cfm>
              <erp>0.2</erp>
            </suspension>
          </ode>
        </physics>
      </joint>
      <joint name='pan' type='revolute'>
        <parent>tripod_floor_link</parent>
        <child>pan_axis_link</child>
        <pose>0 0 0 0 -0 0</pose>
        <axis>
          <xyz>0 0 1</xyz>
          <limit>
            <lower>-3.1416</lower>
            <upper>3.1416</upper>
            <effort>1</effort>
            <velocity>1</velocity>
          </limit>
          <dynamics>
            <spring_reference>0</spring_reference>
            <spring_stiffness>0</spring_stiffness>
            <damping>200</damping>
            <friction>0</friction>
          </dynamics>
        </axis>
        <physics>
          <ode>
            <limit>
              <cfm>0</cfm>
              <erp>0.2</erp>
            </limit>
            <suspension>
              <cfm>0</cfm>
              <erp>0.2</erp>
            </suspension>
          </ode>
        </physics>
      </joint>
      <joint name='sensor_cf_joint' type='fixed'>
        <parent>tilt_axis_link</parent>
        <child>os_sensor</child>
        <pose>0 0 -0 0 -0 0</pose>
        <axis>
          <xyz>0 0 1</xyz>
          <limit>
            <lower>0</lower>
            <upper>0</upper>
            <effort>-1</effort>
            <velocity>-1</velocity>
          </limit>
          <dynamics>
            <spring_reference>0</spring_reference>
            <spring_stiffness>0</spring_stiffness>
            <damping>0</damping>
            <friction>0</friction>
          </dynamics>
        </axis>
        <physics>
          <ode>
            <limit>
              <cfm>0</cfm>
              <erp>0.2</erp>
            </limit>
            <suspension>
              <cfm>0</cfm>
              <erp>0.2</erp>
            </suspension>
          </ode>
        </physics>
      </joint>
      <joint name='tilt' type='revolute'>
        <parent>pan_axis_link</parent>
        <child>tilt_axis_link</child>
        <pose>0 0 -0 0 -0 0</pose>
        <axis>
          <xyz>0 0 1</xyz>
          <limit>
            <lower>-1.9</lower>
            <upper>0.7</upper>
            <effort>100000</effort>
            <velocity>10000</velocity>
          </limit>
          <dynamics>
            <spring_reference>0</spring_reference>
            <spring_stiffness>0</spring_stiffness>
            <damping>180</damping>
            <friction>0</friction>
          </dynamics>
        </axis>
        <physics>
          <ode>
            <limit>
              <cfm>0</cfm>
              <erp>0.2</erp>
            </limit>
            <suspension>
              <cfm>0</cfm>
              <erp>0.2</erp>
            </suspension>
          </ode>
        </physics>
      </joint>
      <static>0</static>
      <allow_auto_disable>1</allow_auto_disable>
  </model>
</sdf>
